Workbook
Name Access: [1]Validation!$E$2:$E$223
Name AccessCircuit: [1]Validation!$C$2:$C$29
Name ACTION: #REF!
Name CoS: [1]Validation!$G$2:$G$47
Name Countries: [1]Validation!$A$2:$A$301
Name Document_array: {"Book1"}
Name DSLCheckService: [1]Validation!$H$2:$H$4
Name fds: {"Book1"}
Name Gói: #REF!
Name Ma_testcase_34: #REF!
Name Port: [1]Validation!$F$2:$F$40
Name QLDH_TDTT_41: #REF!
Name QLHD_CDHD_15: #REF!
Name QLHD_CNHD_34: #REF!
Name QLHD_GHD_34: #REF!
Name QLHD_HHD_13: #REF!
Name QLHD_KHD_6: #REF!
Name QLHD_TH_1: #REF!
Name QLHD_THD_34: #REF!
Name Tên_TestCase: #REF!
Name VancoProducts: [1]Validation!$B$2:$B$4
Name Document_array: {"Book1"}
Name fds: {"Book1"}
Name ACTION: #REF!
Name Document_array: {"Book1"}
Name fds: {"Book1"}
Name Gói: #REF!
Name Ma_testcase_34: #REF!
Name QLDH_TDTT_41: #REF!
Name QLHD_CDHD_15: #REF!
Name QLHD_CNHD_34: #REF!
Name QLHD_GHD_34: #REF!
Name QLHD_HHD_13: #REF!
Name QLHD_KHD_6: #REF!
Name QLHD_TH_1: #REF!
Name QLHD_THD_34: #REF!
Name Tên_TestCase: #REF!
Name ACTION: #REF!
Name Document_array: {"Book1"}
Name fds: {"Book1"}
Name Gói: #REF!
Name Ma_testcase_34: #REF!
Name QLDH_TDTT_41: #REF!
Name QLHD_CDHD_15: #REF!
Name QLHD_CNHD_34: #REF!
Name QLHD_GHD_34: #REF!
Name QLHD_HHD_13: #REF!
Name QLHD_KHD_6: #REF!
Name QLHD_TH_1: #REF!
Name QLHD_THD_34: #REF!
Name Tên_TestCase: #REF!
Name ACTION: #REF!
Name Document_array: {"Book1"}
Name fds: {"Book1"}
Name Ma_testcase_34: #REF!
Name QLDH_TDTT_41: #REF!
Name QLHD_CDHD_15: #REF!
Name QLHD_CNHD_34: #REF!
Name QLHD_GHD_34: #REF!
Name QLHD_HHD_13: #REF!

Sheet Trang bìa
E1: TẬP ĐOÀN VIỄN THÔNG QUÂN ĐỘI
A9: APP VIETTELPAY
A10: TÀI LIỆU KỊCH BẢN KIỂM THỬ CHỨC NĂNG
C16: Mã dự án | D16: :..điền mã dự án
C17: Mã tài liệu | D17: KBKTCN
A20: Người lập: | C20: yennth72
F21: Ngày lập: 02/07/2025
A26: Người kiểm tra: | C26: yennth72
F27: Ngày kiểm tra:
A32: Người phê duyệt:
F33: Ngày phê duyệt:
A37: BẢNG GHI NHẬN THAY ĐỔI TÀI LIỆU
A39: Ngày thay đổi | B39: Vị trí thay đổi | C39: Lý do | D39: Nguồn gốc | E39: Phiên bản cũ | F39: Mô tả thay đổi | G39: Phiên bản mới
A40: 23/04/2026 | C40: Khởi tạo | G40: v1.0

Sheet Giới thiệu
A1: GIỚI THIỆU
A3: 1 - Giới thiệu
A4: KBKTCN CHHS hộ
A6: 2 - Tài liệu tham khảo
A7: STT | B7: Tên tài liệu | C7: Tên file | D7: Phiên bản | E7: Đường dẫn
B8: Story | D8: v1.0
B9: BRD | D9: v1.0
B10: KBNV | D10: v1.0
B11: TLGP | D11: v1.0
D12: v1.0
D13: v1.0
B14: Figma | D14: v1.0
A15: 3 - Môi trường kiểm thử
A16: STT | B16: Môi trường kiểm thử | C16: Thiết bị/trình duyệt | D16: Version | E16: Viết tắt
B17: App VTM ver6.8…../Api…/Tiến trình/Web2.0…. | C17: Điền thiết bị, tool postman, link trình duyệt sử dụng để test | D17: điền ver của hệ điều hành
B19: Cấu hình server test
B20: CPU: 4G, Duecore, Ram 8G, HDD: 320G
B21: Tool test | C21: Phiên bản | E21: Mục đích
B22: SSH secure sheel | E22: Check log hệ thống
B23: Datagrib | E23: Truy vấn CSDL
B24: Jira | E24: Quản lý task, log bug, log work
B25: WIN SCP | E25: Test tiến trình

Sheet Tổng hợp 
A1: TỔNG HỢP KẾT QUẢ KIỂM THỬ
A3: STT | B3: Tên màn hình/chức năng | C3: Manual test | K3: Automation test
C4: Số trường hợp kiểm thử đạt (P) | D4: Số trường hợp kiểm thử không đạt (F) | E4: Số trường hợp kiểm thử đang xem xét (PE) | F4: Số trường hợp kiểm thử chưa thực hiện | G4: Tổng số trường hợp kiểm thử | H4: Tỉ lệ trường hợp kiểm thử đạt (%P) | I4: Tỉ lệ trường hợp kiểm thử không đạt (%F) | J4: Tỉ lệ trường hợp kiểm thử đã thực hiện (%Cover) | K4: Số trường hợp kiểm thử đạt (P) | L4: Số trường hợp kiểm thử không đạt (F) | M4: Số trường hợp kiểm thử đang xem xét (PE) | N4: Số trường hợp kiểm thử chưa thực hiện | O4: Tổng số trường hợp kiểm thử | P4: Tỉ lệ trường hợp kiểm thử đạt (%P) | Q4: Tỉ lệ trường hợp kiểm thử không đạt (%F) | R4: Tỉ lệ trường hợp kiểm thử đã thực hiện (%Cover)
A5: 1 | B5: =template!C3 | C5: =template!C7 | D5: =template!C8 | E5: =template!C9 | F5: =template!C10 | G5: =template!C11 | H5: =C5/G5 | I5: =D5/G5 | J5: =(C5+D5)/G5
A6: Total | C6: =SUM(C5:C5) | D6: =SUM(D5:D5) | E6: =SUM(E5:E5) | F6: =SUM(F5:F5) | G6: =SUM(G5:G5) | H6: =C6/G6 | I6: =D6/G6 | J6: =(C6+D6+E6)/G6

Sheet Cấp lại mật khẩu
B1: KỊCH BẢN KIỂM THỬ CHỨC NĂNG
B3: Tên màn hình/Tên chức năng | C3: Cấp lại mật khẩu
B4: Mã trường hợp kiểm thử
B6: Manual test
B7: Số trường hợp kiểm thử đạt (P) | C7: =COUNTIF($M$18:$M$791,"P")
B8: Số trường hợp kiểm thử không đạt (F) | C8: =COUNTIF($M$18:$M$791,"F")
B9: Số trường hợp kiểm thử đang xem xét (PE) | C9: =COUNTIF($M$18:$M$791,"PE")
B10: Số trường hợp kiểm thử chưa thực hiện | C10: =C11-C7-C8-C9
B11: Tổng số trường hợp kiểm thử | C11: =COUNTA($F$18:$F$362)
A13: ID | B13: Mục đích kiểm thử | C13: Trường hợp kiểm thử | D13: Data test | E13: Các bước thực hiện | F13: Kết quả mong muốn | G13: App | J13: Android | M13: Kết quả (M) | N13: Mã lỗi | O13: Ghi chú
G14: IOS | H14: Android | I14: Lần 3 | J14: Lần 1 | K14: Lần 2 | L14: Lần 3
B15: Suite-1:Kiểm tra accountId
B16: Kiểm tra accountId không tồn tại | D16: curl --location 'http://gw-staging.digital.vn/customer/v1/accounts/recover-pin-app' \ --header 'Product: anim deserunt in ex' \ --header 'Accept-Language: vi' \ --header 'Content-Type: application/json' \ --header 'Accept: application/json' \ --data-raw '{ "accountId": "123123a@" }' | E16: 1. Select * from accounts where id = '1234' 2. Import curl ở mục data test 3. Update accountId = '1234' 4. Run curl | F16: 1. Không có kết quả trả về 4. Trả mã lỗi CS9901=Tài khoản không tồn tại.
B17: Kiểm tra accountId tồn tại | E17: 1. Select * from accounts where id = '01HSTE6K73DCTP6YKP3WZX6QKG' 2. Import curl ở mục data test 3. Update accountId = '01HSTE6K73DCTP6YKP3WZX6QKG' 4. Run curl | F17: 1. Có kết quả bản ghi trả về 4. Thực hiện tiếp check các case bên dưới
B18: Suite-1: Kiểm tra có đi luồng OTP
B19: Kiểm tra tài khoản của KH có đi luồng OTP | C19: Kiểm tra tài khoản vỏ pin, có liên kết thẻ | D19: 1. DB cho vào luồng OTP: SELECT * FROM cdcn_customer_service.global_config WHERE param_name='recover-pin.app.otp-msisdn-list' | E19: 1. Add SĐT vào luồng OTP 2. Vào app VTM 3. Nhập SĐT 4. Bấm Quên mật khẩu 5. Checklog Kibana: staging-cdcn-customer-service | F19: 4.1 App call API cấp lại mật khẩu: /customer/v1/accounts/recover-pin-app 4.2. App show màn đổi mật khẩu 4.3. Huỷ liên kết thẻ: - Push Kafka topic: CANCEL_VM_LINK_TOPIC để hủy - Update DB BANKPLUS: + NAPAS_TOKEN: update status = 3 + LINK_BANK_TOKEN: update status = 3 + EBANKING_SOURCE: update status = 3 + MOBILE_MONEY_SRC: update SRC_STATUS = 3 - Update bảng SOURCE_LINKED DB: update status = 3 - Push kafka topic CANCEL_LINKED_SOURCE để lưu các thuê bao chỉ hủy liên kết tại VT, chưa hủy bên bank | M19: =IF(OR(IF(I19="",IF(H19="",IF(G19="","",G19),H19),I19)="F", IF(L19="",IF(K19="",IF(J19="","",J19), K19),L19)="F")=TRUE,"F", IF(OR(IF(I19="",IF(H19="",IF(G19="","",G19),H19),I19)="PE", IF(L19="",IF(K19="",IF(J19="","",J19), K19),L19)="PE")=TRUE,"PE", IF(AND(IF(I19="",IF(H19="",IF(G19="","",G19),H19),I19)="", IF(L19="",IF(K19="",IF(J19="","",J19), K19),L19)="")=TRUE,"","P")))
E20: 6. Nhập PIN mới 7. Login lại app 8. Bấm vào avatar >> Quản lý nguồn tiền | F20: 6.1. Đổi mật khẩu thành công 6.2. Gửi SMS: Bạn đã đổi mật khẩu thành công, mật khẩu mới là xxxx,…... 7. Login lại = mật khẩu mới thành công 8. Liên kết thẻ trước đó không hiển thị trên app | M20: =IF(OR(IF(I20="",IF(H20="",IF(G20="","",G20),H20),I20)="F", IF(L20="",IF(K20="",IF(J20="","",J20), K20),L20)="F")=TRUE,"F", IF(OR(IF(I20="",IF(H20="",IF(G20="","",G20),H20),I20)="PE", IF(L20="",IF(K20="",IF(J20="","",J20), K20),L20)="PE")=TRUE,"PE", IF(AND(IF(I20="",IF(H20="",IF(G20="","",G20),H20),I20)="", IF(L20="",IF(K20="",IF(J20="","",J20), K20),L20)="")=TRUE,"","P")))
C21: Kiểm tra tài khoản chỉ có VTP, có liên kết thẻ | D21: Liên kết thẻ: - Napas: SaigonBank - Trực tiếp: MB, BIDV, Vpbank - Bán chéo VTP gói -1, 24,26,23,20 | E21: 1. Add SĐT vào luồng OTP 2. Vào app VTM 3. Nhập SĐT 4. Bấm Quên mật khẩu 5. Checklog Kibana: staging-cdcn-customer-service | F21: 4.1 App call API cấp lại mật khẩu: /customer/v1/accounts/recover-pin-app 4.2. App show màn đổi mật khẩu 4.3. Huỷ liên kết thẻ: - Push Kafka topic: CANCEL_VM_LINK_TOPIC để hủy - Update DB BANKPLUS: + NAPAS_TOKEN: update status = 3 + LINK_BANK_TOKEN: update status = 3 + EBANKING_SOURCE: update status = 3 + MOBILE_MONEY_SRC: update SRC_STATUS = 3 - Update bảng SOURCE_LINKED DB: update status = 3 - Push kafka topic CANCEL_LINKED_SOURCE để lưu các thuê bao chỉ hủy liên kết tại VT, chưa hủy bên bank | M21: =IF(OR(IF(I21="",IF(H21="",IF(G21="","",G21),H21),I21)="F", IF(L21="",IF(K21="",IF(J21="","",J21), K21),L21)="F")=TRUE,"F", IF(OR(IF(I21="",IF(H21="",IF(G21="","",G21),H21),I21)="PE", IF(L21="",IF(K21="",IF(J21="","",J21), K21),L21)="PE")=TRUE,"PE", IF(AND(IF(I21="",IF(H21="",IF(G21="","",G21),H21),I21)="", IF(L21="",IF(K21="",IF(J21="","",J21), K21),L21)="")=TRUE,"","P")))
E22: 6. Nhập PIN mới 7. Login lại app 8. Bấm vào avatar >> Quản lý nguồn tiền | F22: 6.1. Đổi mật khẩu thành công 6.2. Gửi SMS: Bạn đã đổi mật khẩu thành công, mật khẩu mới là xxxx,…... 7. Login lại = mật khẩu mới thành công 8. Liên kết thẻ trước đó không hiển thị trên app | M22: =IF(OR(IF(I22="",IF(H22="",IF(G22="","",G22),H22),I22)="F", IF(L22="",IF(K22="",IF(J22="","",J22), K22),L22)="F")=TRUE,"F", IF(OR(IF(I22="",IF(H22="",IF(G22="","",G22),H22),I22)="PE", IF(L22="",IF(K22="",IF(J22="","",J22), K22),L22)="PE")=TRUE,"PE", IF(AND(IF(I22="",IF(H22="",IF(G22="","",G22),H22),I22)="", IF(L22="",IF(K22="",IF(J22="","",J22), K22),L22)="")=TRUE,"","P")))
C23: Kiểm tra tài khoản chỉ có MM, có liên kết thẻ | E23: 1. Add SĐT vào luồng OTP 2. Vào app VTM 3. Nhập SĐT 4. Bấm Quên mật khẩu 5. Checklog Kibana: staging-cdcn-customer-service | F23: 4.1 App call API cấp lại mật khẩu: /customer/v1/accounts/recover-pin-app 4.2. App show màn đổi mật khẩu 4.3. Huỷ liên kết thẻ: - Push Kafka topic: CANCEL_VM_LINK_TOPIC để hủy - Update DB BANKPLUS: + NAPAS_TOKEN: update status = 3 + LINK_BANK_TOKEN: update status = 3 + EBANKING_SOURCE: update status = 3 + MOBILE_MONEY_SRC: update SRC_STATUS = 3 - Update bảng SOURCE_LINKED DB: update status = 3 - Push kafka topic CANCEL_LINKED_SOURCE để lưu các thuê bao chỉ hủy liên kết tại VT, chưa hủy bên bank | M23: =IF(OR(IF(I23="",IF(H23="",IF(G23="","",G23),H23),I23)="F", IF(L23="",IF(K23="",IF(J23="","",J23), K23),L23)="F")=TRUE,"F", IF(OR(IF(I23="",IF(H23="",IF(G23="","",G23),H23),I23)="PE", IF(L23="",IF(K23="",IF(J23="","",J23), K23),L23)="PE")=TRUE,"PE", IF(AND(IF(I23="",IF(H23="",IF(G23="","",G23),H23),I23)="", IF(L23="",IF(K23="",IF(J23="","",J23), K23),L23)="")=TRUE,"","P")))
E24: 6. Nhập PIN mới 7. Login lại app 8. Bấm vào avatar >> Quản lý nguồn tiền | F24: 6.1. Đổi mật khẩu thành công 6.2. Gửi SMS: Bạn đã đổi mật khẩu thành công, mật khẩu mới là xxxx,…... 7. Login lại = mật khẩu mới thành công 8. Liên kết thẻ trước đó không hiển thị trên app | M24: =IF(OR(IF(I24="",IF(H24="",IF(G24="","",G24),H24),I24)="F", IF(L24="",IF(K24="",IF(J24="","",J24), K24),L24)="F")=TRUE,"F", IF(OR(IF(I24="",IF(H24="",IF(G24="","",G24),H24),I24)="PE", IF(L24="",IF(K24="",IF(J24="","",J24), K24),L24)="PE")=TRUE,"PE", IF(AND(IF(I24="",IF(H24="",IF(G24="","",G24),H24),I24)="", IF(L24="",IF(K24="",IF(J24="","",J24), K24),L24)="")=TRUE,"","P")))
C25: Kiểm tra tài khoản có VTT và MM, có liên kết thẻ | D25: VTT gói 20 | E25: 1. Add SĐT vào luồng OTP 2. Vào app VTM 3. Nhập SĐT 4. Bấm Quên mật khẩu 5. Checklog Kibana: staging-cdcn-customer-service | F25: 4.1 App call API cấp lại mật khẩu: /customer/v1/accounts/recover-pin-app 4.2. App show màn đổi mật khẩu 4.3. Huỷ liên kết thẻ: - Push Kafka topic: CANCEL_VM_LINK_TOPIC để hủy - Update DB BANKPLUS: + NAPAS_TOKEN: update status = 3 + LINK_BANK_TOKEN: update status = 3 + EBANKING_SOURCE: update status = 3 + MOBILE_MONEY_SRC: update SRC_STATUS = 3 - Update bảng SOURCE_LINKED DB: update status = 3 - Push kafka topic CANCEL_LINKED_SOURCE để lưu các thuê bao chỉ hủy liên kết tại VT, chưa hủy bên bank | M25: =IF(OR(IF(I25="",IF(H25="",IF(G25="","",G25),H25),I25)="F", IF(L25="",IF(K25="",IF(J25="","",J25), K25),L25)="F")=TRUE,"F", IF(OR(IF(I25="",IF(H25="",IF(G25="","",G25),H25),I25)="PE", IF(L25="",IF(K25="",IF(J25="","",J25), K25),L25)="PE")=TRUE,"PE", IF(AND(IF(I25="",IF(H25="",IF(G25="","",G25),H25),I25)="", IF(L25="",IF(K25="",IF(J25="","",J25), K25),L25)="")=TRUE,"","P")))
E26: 6. Nhập PIN mới 7. Login lại app 8. Bấm vào avatar >> Quản lý nguồn tiền | F26: 6.1. Đổi mật khẩu thành công 6.2. Gửi SMS: Bạn đã đổi mật khẩu thành công, mật khẩu mới là xxxx,…... 7. Login lại = mật khẩu mới thành công 8. Liên kết thẻ trước đó không hiển thị trên app | M26: =IF(OR(IF(I26="",IF(H26="",IF(G26="","",G26),H26),I26)="F", IF(L26="",IF(K26="",IF(J26="","",J26), K26),L26)="F")=TRUE,"F", IF(OR(IF(I26="",IF(H26="",IF(G26="","",G26),H26),I26)="PE", IF(L26="",IF(K26="",IF(J26="","",J26), K26),L26)="PE")=TRUE,"PE", IF(AND(IF(I26="",IF(H26="",IF(G26="","",G26),H26),I26)="", IF(L26="",IF(K26="",IF(J26="","",J26), K26),L26)="")=TRUE,"","P")))
C27: Kiểm tra tài khoản vỏ pin, không có liên kết thẻ | E27: 1. Add SĐT vào luồng OTP 2. Vào app VTM 3. Nhập SĐT 4. Bấm Quên mật khẩu 5. Checklog Kibana: staging-cdcn-customer-service | F27: 4.1 App call API cấp lại mật khẩu: /customer/v1/accounts/recover-pin-app 4.2. App show màn đổi mật khẩu | M27: =IF(OR(IF(I27="",IF(H27="",IF(G27="","",G27),H27),I27)="F", IF(L27="",IF(K27="",IF(J27="","",J27), K27),L27)="F")=TRUE,"F", IF(OR(IF(I27="",IF(H27="",IF(G27="","",G27),H27),I27)="PE", IF(L27="",IF(K27="",IF(J27="","",J27), K27),L27)="PE")=TRUE,"PE", IF(AND(IF(I27="",IF(H27="",IF(G27="","",G27),H27),I27)="", IF(L27="",IF(K27="",IF(J27="","",J27), K27),L27)="")=TRUE,"","P")))
E28: 6. Nhập PIN mới 7. Login lại app 8. Bấm vào avatar >> Quản lý nguồn tiền | F28: 6.1. Đổi mật khẩu thành công 6.2. Gửi SMS: Bạn đã đổi mật khẩu thành công, mật khẩu mới là xxxx,…... 7. Login lại = mật khẩu mới thành công 8. Liên kết thẻ trước đó không hiển thị trên app | M28: =IF(OR(IF(I28="",IF(H28="",IF(G28="","",G28),H28),I28)="F", IF(L28="",IF(K28="",IF(J28="","",J28), K28),L28)="F")=TRUE,"F", IF(OR(IF(I28="",IF(H28="",IF(G28="","",G28),H28),I28)="PE", IF(L28="",IF(K28="",IF(J28="","",J28), K28),L28)="PE")=TRUE,"PE", IF(AND(IF(I28="",IF(H28="",IF(G28="","",G28),H28),I28)="", IF(L28="",IF(K28="",IF(J28="","",J28), K28),L28)="")=TRUE,"","P")))
C29: Kiểm tra tài khoản chỉ có VTP, không có liên kết thẻ | D29: VTP gói -1, 24,26,23,20 | E29: 1. Add SĐT vào luồng OTP 2. Vào app VTM 3. Nhập SĐT 4. Bấm Quên mật khẩu 5. Checklog Kibana: staging-cdcn-customer-service | F29: 4.1 App call API cấp lại mật khẩu: /customer/v1/accounts/recover-pin-app 4.2. App show màn đổi mật khẩu | M29: =IF(OR(IF(I29="",IF(H29="",IF(G29="","",G29),H29),I29)="F", IF(L29="",IF(K29="",IF(J29="","",J29), K29),L29)="F")=TRUE,"F", IF(OR(IF(I29="",IF(H29="",IF(G29="","",G29),H29),I29)="PE", IF(L29="",IF(K29="",IF(J29="","",J29), K29),L29)="PE")=TRUE,"PE", IF(AND(IF(I29="",IF(H29="",IF(G29="","",G29),H29),I29)="", IF(L29="",IF(K29="",IF(J29="","",J29), K29),L29)="")=TRUE,"","P")))
E30: 6. Nhập PIN mới 7. Login lại app 8. Bấm vào avatar >> Quản lý nguồn tiền | F30: 6.1. Đổi mật khẩu thành công 6.2. Gửi SMS: Bạn đã đổi mật khẩu thành công, mật khẩu mới là xxxx,…... 7. Login lại = mật khẩu mới thành công 8. Liên kết thẻ trước đó không hiển thị trên app | M30: =IF(OR(IF(I30="",IF(H30="",IF(G30="","",G30),H30),I30)="F", IF(L30="",IF(K30="",IF(J30="","",J30), K30),L30)="F")=TRUE,"F", IF(OR(IF(I30="",IF(H30="",IF(G30="","",G30),H30),I30)="PE", IF(L30="",IF(K30="",IF(J30="","",J30), K30),L30)="PE")=TRUE,"PE", IF(AND(IF(I30="",IF(H30="",IF(G30="","",G30),H30),I30)="", IF(L30="",IF(K30="",IF(J30="","",J30), K30),L30)="")=TRUE,"","P")))
C31: Kiểm tra tài khoản chỉ có MM, không có liên kết thẻ | E31: 1. Add SĐT vào luồng OTP 2. Vào app VTM 3. Nhập SĐT 4. Bấm Quên mật khẩu 5. Checklog Kibana: staging-cdcn-customer-service | F31: 4.1 App call API cấp lại mật khẩu: /customer/v1/accounts/recover-pin-app 4.2. App show màn đổi mật khẩu | M31: =IF(OR(IF(I31="",IF(H31="",IF(G31="","",G31),H31),I31)="F", IF(L31="",IF(K31="",IF(J31="","",J31), K31),L31)="F")=TRUE,"F", IF(OR(IF(I31="",IF(H31="",IF(G31="","",G31),H31),I31)="PE", IF(L31="",IF(K31="",IF(J31="","",J31), K31),L31)="PE")=TRUE,"PE", IF(AND(IF(I31="",IF(H31="",IF(G31="","",G31),H31),I31)="", IF(L31="",IF(K31="",IF(J31="","",J31), K31),L31)="")=TRUE,"","P")))
E32: 6. Nhập PIN mới 7. Login lại app 8. Bấm vào avatar >> Quản lý nguồn tiền | F32: 6.1. Đổi mật khẩu thành công 6.2. Gửi SMS: Bạn đã đổi mật khẩu thành công, mật khẩu mới là xxxx,…... 7. Login lại = mật khẩu mới thành công 8. Liên kết thẻ trước đó không hiển thị trên app | M32: =IF(OR(IF(I32="",IF(H32="",IF(G32="","",G32),H32),I32)="F", IF(L32="",IF(K32="",IF(J32="","",J32), K32),L32)="F")=TRUE,"F", IF(OR(IF(I32="",IF(H32="",IF(G32="","",G32),H32),I32)="PE", IF(L32="",IF(K32="",IF(J32="","",J32), K32),L32)="PE")=TRUE,"PE", IF(AND(IF(I32="",IF(H32="",IF(G32="","",G32),H32),I32)="", IF(L32="",IF(K32="",IF(J32="","",J32), K32),L32)="")=TRUE,"","P")))
C33: Kiểm tra tài khoản có VTT và MM, không có liên kết thẻ | D33: VTP gói 20 | E33: 1. Add SĐT vào luồng OTP 2. Vào app VTM 3. Nhập SĐT 4. Bấm Quên mật khẩu 5. Checklog Kibana: staging-cdcn-customer-service | F33: 4.1 App call API cấp lại mật khẩu: /customer/v1/accounts/recover-pin-app 4.2. App show màn đổi mật khẩu | M33: =IF(OR(IF(I33="",IF(H33="",IF(G33="","",G33),H33),I33)="F", IF(L33="",IF(K33="",IF(J33="","",J33), K33),L33)="F")=TRUE,"F", IF(OR(IF(I33="",IF(H33="",IF(G33="","",G33),H33),I33)="PE", IF(L33="",IF(K33="",IF(J33="","",J33), K33),L33)="PE")=TRUE,"PE", IF(AND(IF(I33="",IF(H33="",IF(G33="","",G33),H33),I33)="", IF(L33="",IF(K33="",IF(J33="","",J33), K33),L33)="")=TRUE,"","P")))
E34: 6. Nhập PIN mới 7. Login lại app 8. Bấm vào avatar >> Quản lý nguồn tiền | F34: 6.1. Đổi mật khẩu thành công 6.2. Gửi SMS: Bạn đã đổi mật khẩu thành công, mật khẩu mới là xxxx,…... 7. Login lại = mật khẩu mới thành công 8. Liên kết thẻ trước đó không hiển thị trên app | M34: =IF(OR(IF(I34="",IF(H34="",IF(G34="","",G34),H34),I34)="F", IF(L34="",IF(K34="",IF(J34="","",J34), K34),L34)="F")=TRUE,"F", IF(OR(IF(I34="",IF(H34="",IF(G34="","",G34),H34),I34)="PE", IF(L34="",IF(K34="",IF(J34="","",J34), K34),L34)="PE")=TRUE,"PE", IF(AND(IF(I34="",IF(H34="",IF(G34="","",G34),H34),I34)="", IF(L34="",IF(K34="",IF(J34="","",J34), K34),L34)="")=TRUE,"","P")))
B35: Kiểm tra tài khoản của KH không đi luồng OTP | C35: Kiểm tra tài khoản vỏ pin | D35: 1. DB cho vào luồng OTP: SELECT * FROM cdcn_customer_service.global_config WHERE param_name='recover-pin.app.otp-msisdn-list' | E35: 1. Bỏ SĐT vào luồng OTP 2. Vào app VTM 3. Nhập SĐT 4. Bấm Quên mật khẩu 5. Checklog Kibana: staging-cdcn-customer-service | F35: 4. Đi tiếp case kiểm tra trạng thái tài khoản bên dưới | M35: =IF(OR(IF(I35="",IF(H35="",IF(G35="","",G35),H35),I35)="F", IF(L35="",IF(K35="",IF(J35="","",J35), K35),L35)="F")=TRUE,"F", IF(OR(IF(I35="",IF(H35="",IF(G35="","",G35),H35),I35)="PE", IF(L35="",IF(K35="",IF(J35="","",J35), K35),L35)="PE")=TRUE,"PE", IF(AND(IF(I35="",IF(H35="",IF(G35="","",G35),H35),I35)="", IF(L35="",IF(K35="",IF(J35="","",J35), K35),L35)="")=TRUE,"","P")))
C36: Kiểm tra tài khoản chỉ có VTP | D36: VTP gói -1, 24,26,23,20 | E36: 1. Bỏ SĐT vào luồng OTP 2. Vào app VTM 3. Nhập SĐT 4. Bấm Quên mật khẩu 5. Checklog Kibana: staging-cdcn-customer-service | F36: 4. Đi tiếp case kiểm tra trạng thái tài khoản bên dưới | M36: =IF(OR(IF(I36="",IF(H36="",IF(G36="","",G36),H36),I36)="F", IF(L36="",IF(K36="",IF(J36="","",J36), K36),L36)="F")=TRUE,"F", IF(OR(IF(I36="",IF(H36="",IF(G36="","",G36),H36),I36)="PE", IF(L36="",IF(K36="",IF(J36="","",J36), K36),L36)="PE")=TRUE,"PE", IF(AND(IF(I36="",IF(H36="",IF(G36="","",G36),H36),I36)="", IF(L36="",IF(K36="",IF(J36="","",J36), K36),L36)="")=TRUE,"","P")))
C37: Kiểm tra tài khoản chỉ có MM | E37: 1. Bỏ SĐT vào luồng OTP 2. Vào app VTM 3. Nhập SĐT 4. Bấm Quên mật khẩu 5. Checklog Kibana: staging-cdcn-customer-service | F37: 4. Đi tiếp case kiểm tra trạng thái tài khoản bên dưới | M37: =IF(OR(IF(I37="",IF(H37="",IF(G37="","",G37),H37),I37)="F", IF(L37="",IF(K37="",IF(J37="","",J37), K37),L37)="F")=TRUE,"F", IF(OR(IF(I37="",IF(H37="",IF(G37="","",G37),H37),I37)="PE", IF(L37="",IF(K37="",IF(J37="","",J37), K37),L37)="PE")=TRUE,"PE", IF(AND(IF(I37="",IF(H37="",IF(G37="","",G37),H37),I37)="", IF(L37="",IF(K37="",IF(J37="","",J37), K37),L37)="")=TRUE,"","P")))
C38: Kiểm tra tài khoản có VTT và MM | D38: VTP gói 20 | E38: 1. Bỏ SĐT vào luồng OTP 2. Vào app VTM 3. Nhập SĐT 4. Bấm Quên mật khẩu 5. Checklog Kibana: staging-cdcn-customer-service | F38: 4. Đi tiếp case kiểm tra trạng thái tài khoản bên dưới | M38: =IF(OR(IF(I38="",IF(H38="",IF(G38="","",G38),H38),I38)="F", IF(L38="",IF(K38="",IF(J38="","",J38), K38),L38)="F")=TRUE,"F", IF(OR(IF(I38="",IF(H38="",IF(G38="","",G38),H38),I38)="PE", IF(L38="",IF(K38="",IF(J38="","",J38), K38),L38)="PE")=TRUE,"PE", IF(AND(IF(I38="",IF(H38="",IF(G38="","",G38),H38),I38)="", IF(L38="",IF(K38="",IF(J38="","",J38), K38),L38)="")=TRUE,"","P")))
B39: Suite-1: Kiểm tra trạng thái tài khoản
B40: Kiểm tra tài khoản có account.status = 2 (LOCKED) | C40: Kiểm tra tài khoản vỏ pin, có liên kết thẻ | D40: 1. DB cho vào luồng OTP: SELECT * FROM cdcn_customer_service.global_config WHERE param_name='recover-pin.app.otp-msisdn-list' | E40: 1. Bỏ SĐT vào luồng OTP 2. Vào app VTM 3. Nhập SĐT 4. Bấm Quên mật khẩu 5. Checklog Kibana: staging-cdcn-customer-service | F40: 4.1 App call API cấp lại mật khẩu: /customer/v1/accounts/recover-pin-app 4.2. App show màn đổi mật khẩu 4.3. Huỷ liên kết thẻ: - Push Kafka topic: CANCEL_VM_LINK_TOPIC để hủy - Update DB BANKPLUS: + NAPAS_TOKEN: update status = 3 + LINK_BANK_TOKEN: update status = 3 + EBANKING_SOURCE: update status = 3 + MOBILE_MONEY_SRC: update SRC_STATUS = 3 - Update bảng SOURCE_LINKED DB: update status = 3 - Push kafka topic CANCEL_LINKED_SOURCE để lưu các thuê bao chỉ hủy liên kết tại VT, chưa hủy bên bank | M40: =IF(OR(IF(I40="",IF(H40="",IF(G40="","",G40),H40),I40)="F", IF(L40="",IF(K40="",IF(J40="","",J40), K40),L40)="F")=TRUE,"F", IF(OR(IF(I40="",IF(H40="",IF(G40="","",G40),H40),I40)="PE", IF(L40="",IF(K40="",IF(J40="","",J40), K40),L40)="PE")=TRUE,"PE", IF(AND(IF(I40="",IF(H40="",IF(G40="","",G40),H40),I40)="", IF(L40="",IF(K40="",IF(J40="","",J40), K40),L40)="")=TRUE,"","P")))
E41: 6. Nhập PIN mới 7. Login lại app 8. Bấm vào avatar >> Quản lý nguồn tiền | F41: 6.1. Đổi mật khẩu thành công 6.2. Gửi SMS: Bạn đã đổi mật khẩu thành công, mật khẩu mới là xxxx,…... 7. Login lại = mật khẩu mới thành công 8. Liên kết thẻ trước đó không hiển thị trên app | M41: =IF(OR(IF(I41="",IF(H41="",IF(G41="","",G41),H41),I41)="F", IF(L41="",IF(K41="",IF(J41="","",J41), K41),L41)="F")=TRUE,"F", IF(OR(IF(I41="",IF(H41="",IF(G41="","",G41),H41),I41)="PE", IF(L41="",IF(K41="",IF(J41="","",J41), K41),L41)="PE")=TRUE,"PE", IF(AND(IF(I41="",IF(H41="",IF(G41="","",G41),H41),I41)="", IF(L41="",IF(K41="",IF(J41="","",J41), K41),L41)="")=TRUE,"","P")))
C42: Kiểm tra tài khoản chỉ có VTP, có liên kết thẻ | D42: Liên kết thẻ: - Napas: SaigonBank - Trực tiếp: MB, BIDV, Vpbank - Bán chéo VTP gói -1, 24,26,23,20 | E42: 1. Bỏ SĐT vào luồng OTP 2. Vào app VTM 3. Nhập SĐT 4. Bấm Quên mật khẩu 5. Checklog Kibana: staging-cdcn-customer-service | F42: 4.1 App call API cấp lại mật khẩu: /customer/v1/accounts/recover-pin-app 4.2. App show màn đổi mật khẩu 4.3. Huỷ liên kết thẻ: - Push Kafka topic: CANCEL_VM_LINK_TOPIC để hủy - Update DB BANKPLUS: + NAPAS_TOKEN: update status = 3 + LINK_BANK_TOKEN: update status = 3 + EBANKING_SOURCE: update status = 3 + MOBILE_MONEY_SRC: update SRC_STATUS = 3 - Update bảng SOURCE_LINKED DB: update status = 3 - Push kafka topic CANCEL_LINKED_SOURCE để lưu các thuê bao chỉ hủy liên kết tại VT, chưa hủy bên bank | M42: =IF(OR(IF(I42="",IF(H42="",IF(G42="","",G42),H42),I42)="F", IF(L42="",IF(K42="",IF(J42="","",J42), K42),L42)="F")=TRUE,"F", IF(OR(IF(I42="",IF(H42="",IF(G42="","",G42),H42),I42)="PE", IF(L42="",IF(K42="",IF(J42="","",J42), K42),L42)="PE")=TRUE,"PE", IF(AND(IF(I42="",IF(H42="",IF(G42="","",G42),H42),I42)="", IF(L42="",IF(K42="",IF(J42="","",J42), K42),L42)="")=TRUE,"","P")))
E43: 6. Nhập PIN mới 7. Login lại app 8. Bấm vào avatar >> Quản lý nguồn tiền | F43: 6.1. Đổi mật khẩu thành công 6.2. Gửi SMS: Bạn đã đổi mật khẩu thành công, mật khẩu mới là xxxx,…... 7. Login lại = mật khẩu mới thành công 8. Liên kết thẻ trước đó không hiển thị trên app | M43: =IF(OR(IF(I43="",IF(H43="",IF(G43="","",G43),H43),I43)="F", IF(L43="",IF(K43="",IF(J43="","",J43), K43),L43)="F")=TRUE,"F", IF(OR(IF(I43="",IF(H43="",IF(G43="","",G43),H43),I43)="PE", IF(L43="",IF(K43="",IF(J43="","",J43), K43),L43)="PE")=TRUE,"PE", IF(AND(IF(I43="",IF(H43="",IF(G43="","",G43),H43),I43)="", IF(L43="",IF(K43="",IF(J43="","",J43), K43),L43)="")=TRUE,"","P")))
...

Sheet template
C3: Tên màn hình/Tên chức năng | D3: tên module
C4: Mã trường hợp kiểm thử
C6: Manual test
C7: Số trường hợp kiểm thử đạt (P) | D7: =COUNTIF($O$16:$O$1702,"P")
C8: Số trường hợp kiểm thử không đạt (F) | D8: =COUNTIF($O$16:$O$387,"F")
C9: Số trường hợp kiểm thử đang xem xét (PE) | D9: =COUNTIF($O$16:$O$387,"PE")
C10: Số trường hợp kiểm thử chưa thực hiện | D10: =D11-D7-D8-D9
C11: Tổng số trường hợp kiểm thử | D11: =COUNTA($G$16:$G$382)
A13: ID | B13: Mức độ ưu tiên | C13: Mục đích kiểm thử | D13: Trường hợp kiểm thử | E13: Data test | F13: Các bước thực hiện | G13: Kết quả mong muốn | H13: Ảnh màn hình | I13: IOS | L13: Android | O13: Kết quả (M) | P13: Mã lỗi | Q13: Ghi chú
I14: Lần 1 | J14: Lần 2 | K14: Lần 3 | L14: Lần 1 | M14: Lần 2 | N14: Lần 3
C15: Suite-1:
O16: =IF(OR(IF(K16="",IF(J16="",IF(I16="","",I16),J16),K16)="F", IF(N16="",IF(M16="",IF(L16="","",L16), M16),N16)="F")=TRUE,"F", IF(OR(IF(K16="",IF(J16="",IF(I16="","",I16),J16),K16)="PE", IF(N16="",IF(M16="",IF(L16="","",L16), M16),N16)="PE")=TRUE,"PE", IF(AND(IF(K16="",IF(J16="",IF(I16="","",I16),J16),K16)="", IF(N16="",IF(M16="",IF(L16="","",L16), M16),N16)="")=TRUE,"","P")))
O17: =IF(OR(IF(K17="",IF(J17="",IF(I17="","",I17),J17),K17)="F", IF(N17="",IF(M17="",IF(L17="","",L17), M17),N17)="F")=TRUE,"F", IF(OR(IF(K17="",IF(J17="",IF(I17="","",I17),J17),K17)="PE", IF(N17="",IF(M17="",IF(L17="","",L17), M17),N17)="PE")=TRUE,"PE", IF(AND(IF(K17="",IF(J17="",IF(I17="","",I17),J17),K17)="", IF(N17="",IF(M17="",IF(L17="","",L17), M17),N17)="")=TRUE,"","P")))
O18: =IF(OR(IF(K18="",IF(J18="",IF(I18="","",I18),J18),K18)="F", IF(N18="",IF(M18="",IF(L18="","",L18), M18),N18)="F")=TRUE,"F", IF(OR(IF(K18="",IF(J18="",IF(I18="","",I18),J18),K18)="PE", IF(N18="",IF(M18="",IF(L18="","",L18), M18),N18)="PE")=TRUE,"PE", IF(AND(IF(K18="",IF(J18="",IF(I18="","",I18),J18),K18)="", IF(N18="",IF(M18="",IF(L18="","",L18), M18),N18)="")=TRUE,"","P")))
O19: =IF(OR(IF(K19="",IF(J19="",IF(I19="","",I19),J19),K19)="F", IF(N19="",IF(M19="",IF(L19="","",L19), M19),N19)="F")=TRUE,"F", IF(OR(IF(K19="",IF(J19="",IF(I19="","",I19),J19),K19)="PE", IF(N19="",IF(M19="",IF(L19="","",L19), M19),N19)="PE")=TRUE,"PE", IF(AND(IF(K19="",IF(J19="",IF(I19="","",I19),J19),K19)="", IF(N19="",IF(M19="",IF(L19="","",L19), M19),N19)="")=TRUE,"","P")))
O20: =IF(OR(IF(K20="",IF(J20="",IF(I20="","",I20),J20),K20)="F", IF(N20="",IF(M20="",IF(L20="","",L20), M20),N20)="F")=TRUE,"F", IF(OR(IF(K20="",IF(J20="",IF(I20="","",I20),J20),K20)="PE", IF(N20="",IF(M20="",IF(L20="","",L20), M20),N20)="PE")=TRUE,"PE", IF(AND(IF(K20="",IF(J20="",IF(I20="","",I20),J20),K20)="", IF(N20="",IF(M20="",IF(L20="","",L20), M20),N20)="")=TRUE,"","P")))
O21: =IF(OR(IF(K21="",IF(J21="",IF(I21="","",I21),J21),K21)="F", IF(N21="",IF(M21="",IF(L21="","",L21), M21),N21)="F")=TRUE,"F", IF(OR(IF(K21="",IF(J21="",IF(I21="","",I21),J21),K21)="PE", IF(N21="",IF(M21="",IF(L21="","",L21), M21),N21)="PE")=TRUE,"PE", IF(AND(IF(K21="",IF(J21="",IF(I21="","",I21),J21),K21)="", IF(N21="",IF(M21="",IF(L21="","",L21), M21),N21)="")=TRUE,"","P")))
O22: =IF(OR(IF(K22="",IF(J22="",IF(I22="","",I22),J22),K22)="F", IF(N22="",IF(M22="",IF(L22="","",L22), M22),N22)="F")=TRUE,"F", IF(OR(IF(K22="",IF(J22="",IF(I22="","",I22),J22),K22)="PE", IF(N22="",IF(M22="",IF(L22="","",L22), M22),N22)="PE")=TRUE,"PE", IF(AND(IF(K22="",IF(J22="",IF(I22="","",I22),J22),K22)="", IF(N22="",IF(M22="",IF(L22="","",L22), M22),N22)="")=TRUE,"","P")))
O23: =IF(OR(IF(K23="",IF(J23="",IF(I23="","",I23),J23),K23)="F", IF(N23="",IF(M23="",IF(L23="","",L23), M23),N23)="F")=TRUE,"F", IF(OR(IF(K23="",IF(J23="",IF(I23="","",I23),J23),K23)="PE", IF(N23="",IF(M23="",IF(L23="","",L23), M23),N23)="PE")=TRUE,"PE", IF(AND(IF(K23="",IF(J23="",IF(I23="","",I23),J23),K23)="", IF(N23="",IF(M23="",IF(L23="","",L23), M23),N23)="")=TRUE,"","P")))
O24: =IF(OR(IF(K24="",IF(J24="",IF(I24="","",I24),J24),K24)="F", IF(N24="",IF(M24="",IF(L24="","",L24), M24),N24)="F")=TRUE,"F", IF(OR(IF(K24="",IF(J24="",IF(I24="","",I24),J24),K24)="PE", IF(N24="",IF(M24="",IF(L24="","",L24), M24),N24)="PE")=TRUE,"PE", IF(AND(IF(K24="",IF(J24="",IF(I24="","",I24),J24),K24)="", IF(N24="",IF(M24="",IF(L24="","",L24), M24),N24)="")=TRUE,"","P")))
O25: =IF(OR(IF(K25="",IF(J25="",IF(I25="","",I25),J25),K25)="F", IF(N25="",IF(M25="",IF(L25="","",L25), M25),N25)="F")=TRUE,"F", IF(OR(IF(K25="",IF(J25="",IF(I25="","",I25),J25),K25)="PE", IF(N25="",IF(M25="",IF(L25="","",L25), M25),N25)="PE")=TRUE,"PE", IF(AND(IF(K25="",IF(J25="",IF(I25="","",I25),J25),K25)="", IF(N25="",IF(M25="",IF(L25="","",L25), M25),N25)="")=TRUE,"","P")))
O26: =IF(OR(IF(K26="",IF(J26="",IF(I26="","",I26),J26),K26)="F", IF(N26="",IF(M26="",IF(L26="","",L26), M26),N26)="F")=TRUE,"F", IF(OR(IF(K26="",IF(J26="",IF(I26="","",I26),J26),K26)="PE", IF(N26="",IF(M26="",IF(L26="","",L26), M26),N26)="PE")=TRUE,"PE", IF(AND(IF(K26="",IF(J26="",IF(I26="","",I26),J26),K26)="", IF(N26="",IF(M26="",IF(L26="","",L26), M26),N26)="")=TRUE,"","P")))
O27: =IF(OR(IF(K27="",IF(J27="",IF(I27="","",I27),J27),K27)="F", IF(N27="",IF(M27="",IF(L27="","",L27), M27),N27)="F")=TRUE,"F", IF(OR(IF(K27="",IF(J27="",IF(I27="","",I27),J27),K27)="PE", IF(N27="",IF(M27="",IF(L27="","",L27), M27),N27)="PE")=TRUE,"PE", IF(AND(IF(K27="",IF(J27="",IF(I27="","",I27),J27),K27)="", IF(N27="",IF(M27="",IF(L27="","",L27), M27),N27)="")=TRUE,"","P")))
... O206: =IF(OR(IF(K206="",IF(J206="",IF(I206="","",I206),J206),K206)="F", IF(N206="",IF(M206="",IF(L206="","",L206), M206),N206)="F")=TRUE,"F", IF(OR(IF(K206="",IF(J206="",IF(I206="","",I206),J206),K206)="PE", IF(N206="",IF(M206="",IF(L206="","",L206), M206),N206)="PE")=TRUE,"PE", IF(AND(IF(K206="",IF(J206="",IF(I206="","",I206),J206),K206)="", IF(N206="",IF(M206="",IF(L206="","",L206), M206),N206)="")=TRUE,"","P")))

Sheet Note
A1: select * from auto_recharge_setting where msisdn = '84961120855'; -- lưu thông tin đăng ký NTĐ của user
A2: select * from auto_recharge_transaction; order by created_time desc ; where core_order_id = '251112549030370'; -- Lưu event consume được từ kafka BĐSD hoặc Đăng ký hoặc kết quả nạp
A3: select * from auto_recharge_transaction_history order by created_time desc ; where core_order_id = '01K9VM6GFQ28HC7XBG96EPX0MP'; -- Lưu khi đã xử lý xong (tức kết quả NTĐ core recharge trả về)
A4: select * from auto_recharge_transaction_history where setting_id = '85' order by created_time desc ;
A5: select * from auto_recharge_transaction; where setting_id = '71'; where reference_id = '109251121140915812';
A6: select * from auto_recharge_transaction where setting_id = '115' order by created_time desc;
A7: select * from auto_recharge_transaction_history where reference_id = '109251121140915812' ;
A8: select * from global_config where param_name = 'min.recharge.amount' ; -- cấu hình min_amount
A9: select * from global_config where param_name = 'process.max.retry.processing.count'; -- cấu hình max số lần retry xử lý lại
A10: select * from global_config where param_name = 'process.retry.processing.interval'; -- time cách mỗi lần retry
A11: select * from global_config where param_name = 'process.max.retry.query.result.count'; -- cấu hình retry tiến trình xử lý truy vấn kết quả timeout
A12: select * from global_config where param_name = 'auto.recharge.whitelist.bankcode'; -- cấu hình được nạp vào nguồn tiền nào
... A65: }
